#VRML_SIM R2023b utf8

EXTERNPROTO "https://raw.githubusercontent.com/cyberbotics/webots/R2023b/projects/objects/backgrounds/protos/TexturedBackground.proto"
EXTERNPROTO "https://raw.githubusercontent.com/cyberbotics/webots/R2023b/projects/objects/backgrounds/protos/TexturedBackgroundLight.proto"
EXTERNPROTO "https://raw.githubusercontent.com/cyberbotics/webots/R2023b/projects/objects/floors/protos/RectangleArena.proto"

WorldInfo {
  basicTimeStep 8
}
Viewpoint {
  orientation -0.12095342882342655 -0.5387619541317107 -0.8337300671296657 5.030191435733009
  position -1.5009237348070141 -4.244755134617764 1.844672089336917
}
TexturedBackground {
}
TexturedBackgroundLight {
}
RectangleArena {
  floorSize 10 10
}
Robot {
  translation 0 0 0.49
  children [
    Shape {
      appearance DEF base_link_material PBRAppearance {
        roughness 1
        metalness 0
      }
      geometry DEF base_link Mesh {
        url [
          "D:/FxxkingCodes/Webots/FlyCar/protos/flycar/flycar/meshes/base_link.STL"
        ]
      }
    }
    Solid {
      translation -0.29643 -0.16443 0.12194
      rotation 1 0 0 1.5708
      children [
        Shape {
          appearance DEF shan1_material PBRAppearance {
            roughness 1
            metalness 0
          }
          geometry DEF shan1 Mesh {
            url [
              "D:/FxxkingCodes/Webots/FlyCar/protos/flycar/flycar/meshes/shan1.STL"
            ]
          }
        }
      ]
      name "shan1"
      boundingObject USE shan1
      physics Physics {
        density -1
        mass 0.091059
        centerOfMass [
          0.013051 0.006709 0.380735
        ]
        inertiaMatrix [
          0.0002544302 0.0004721584 0.0002578507
          3.988325e-12 9.876693e-06 2.735851e-11
        ]
      }
    }
    Solid {
      translation 0.22399 -0.60211 0.092336
      rotation 0.741385924676306 0.4745249517889792 0.4745239517890808 1.865666
      children [
        Shape {
          appearance DEF shan2_material PBRAppearance {
            roughness 1
            metalness 0
          }
          geometry DEF shan2 Mesh {
            url [
              "D:/FxxkingCodes/Webots/FlyCar/protos/flycar/flycar/meshes/shan2.STL"
            ]
          }
        }
      ]
      name "shan2"
      boundingObject USE shan2
      physics Physics {
        density -1
        mass 0.091059
        centerOfMass [
          0.061323 0.036313 -0.002994
        ]
        inertiaMatrix [
          0.0002625418 0.0004721584 0.000249739
          1.507028e-11 7.713373e-06 2.320213e-11
        ]
      }
    }
    Solid {
      translation 0.26 -0.39557 0.12194
      rotation -3.000001192953712e-06 0.707108281182371 0.7071052811811781 3.141598
      children [
        Shape {
          appearance DEF fist PBRAppearance {
            roughness 1
            metalness 0
          }
          geometry DEF shan3 Mesh {
            url [
              "D:/FxxkingCodes/Webots/FlyCar/protos/flycar/flycar/meshes/shan3.STL"
            ]
          }
        }
      ]
      name "shan3"
      boundingObject USE shan3
      physics Physics {
        density -1
        mass 0.091059
        centerOfMass [
          0.013051 0.006709 0.380735
        ]
        inertiaMatrix [
          0.0002544302 0.0004721584 0.0002578507
          3.971036e-12 9.876691e-06 2.738173e-11
        ]
      }
    }
    Solid {
      translation 0.097357 -0.001784 0.12194
      rotation -0.5773496025226483 0.5773516025212714 -0.5773496025226483 2.094399
      children [
        Shape {
          appearance DEF sahn4_material PBRAppearance {
            roughness 1
            metalness 0
          }
          geometry DEF sahn4 Mesh {
            url [
              "D:/FxxkingCodes/Webots/FlyCar/protos/flycar/flycar/meshes/sahn4.STL"
            ]
          }
        }
      ]
      name "sahn4"
      boundingObject USE sahn4
      physics Physics {
        density -1
        mass 0.091059
        centerOfMass [
          0.013051 -0.006709 -0.380735
        ]
        inertiaMatrix [
          0.0002544302 0.0004721584 0.0002578507
          -3.985093e-12 -9.876691e-06 2.736447e-11
        ]
      }
    }
    Solid {
      translation 0.094742 -0.355 -0.11666
      rotation 1 0 0 1.5708
      children [
        Shape {
          appearance DEF tou_material PBRAppearance {
            baseColor 0.792157 0.819608 0.933333
            roughness 1
            metalness 0
          }
          geometry DEF tou Mesh {
            url [
              "D:/FxxkingCodes/Webots/FlyCar/protos/flycar/flycar/meshes/tou.STL"
            ]
          }
        }
        HingeJoint {
          jointParameters HingeJointParameters {
            axis 0 0 1
            anchor -0.15637 0.068631 0.013
          }
          device [
            RotationalMotor {
              name "left hip"
              maxTorque 10000
            }
            PositionSensor {
              name "left hip_sensor"
            }
          ]
          endPoint Solid {
            translation -0.15637 0.068631 0.013
            rotation 0 0 -1 0.5076099999999998
            children [
              Shape {
                appearance DEF zuo_material PBRAppearance {
                  baseColor 0.792157 0.819608 0.933333
                  roughness 1
                  metalness 0
                }
                geometry DEF zuo Mesh {
                  url [
                    "D:/FxxkingCodes/Webots/FlyCar/protos/flycar/flycar/meshes/zuo.STL"
                  ]
                }
              }
              HingeJoint {
                jointParameters HingeJointParameters {
                  axis 0 0 1
                  anchor 0.36022 0.059837 0.005
                }
                device [
                  RotationalMotor {
                    name "left ankle"
                    maxTorque 10000
                  }
                  PositionSensor {
                    name "left ankle_sensor"
                  }
                ]
                endPoint Solid {
                  translation 0.36022 0.059837 0.005
                  rotation 0 0 1 0.9236899999999999
                  children [
                    Shape {
                      appearance DEF zuoxia_material PBRAppearance {
                        baseColor 0.792157 0.819608 0.933333
                        roughness 1
                        metalness 0
                      }
                      geometry DEF zuoxia Mesh {
                        url [
                          "D:/FxxkingCodes/Webots/FlyCar/protos/flycar/flycar/meshes/zuoxia.STL"
                        ]
                      }
                    }
                    HingeJoint {
                      jointParameters HingeJointParameters {
                        axis 0 0 1
                        anchor -0.376 0 0.025
                      }
                      device [
                        RotationalMotor {
                          name "left wheel"
                          maxTorque 10000
                        }
                        PositionSensor {
                          name "left wheel_sensor"
                        }
                      ]
                      endPoint Solid {
                        translation -0.376 0 0.025
                        rotation 0 0 -1 0.5493
                        children [
                          Shape {
                            appearance DEF lun1_material PBRAppearance {
                              baseColor 0.792157 0.819608 0.933333
                              roughness 1
                              metalness 0
                            }
                            geometry DEF lun1 Mesh {
                              url [
                                "D:/FxxkingCodes/Webots/FlyCar/protos/flycar/flycar/meshes/lun1.STL"
                              ]
                            }
                          }
                        ]
                        name "lun1"
                        boundingObject USE lun1
                        physics Physics {
                          density -1
                          mass 0.297523
                          centerOfMass [
                            0 0 0.015
                          ]
                          inertiaMatrix [
                            0.0004360678 0.0004360678 0.000830824
                            -2.168404e-19 -1.579262e-19 2.714651e-19
                          ]
                        }
                      }
                    }
                  ]
                  name "zuoxia"
                  boundingObject USE zuoxia
                  physics Physics {
                    density -1
                    mass 0.327867
                    centerOfMass [
                      -0.194915 0 0.01
                    ]
                    inertiaMatrix [
                      0.0001051654 0.004955725 0.005039033
                      5.834363e-18 -6.638045e-18 4.652289e-20
                    ]
                  }
                }
              }
            ]
            name "zuo"
            boundingObject USE zuo
            physics Physics {
              density -1
              mass 0.254971
              centerOfMass [
                0.071672 0 0.015
              ]
              inertiaMatrix [
                0.0001439139 0.002468255 0.002572906
                3.184844e-19 -3.244073e-18 -9.747643e-20
              ]
            }
          }
        }
        HingeJoint {
          jointParameters HingeJointParameters {
            axis 0 0 1
            anchor -0.045 0.18 -0.163
          }
          device [
            RotationalMotor {
              name "right hip"
              maxTorque 10000
            }
            PositionSensor {
              name "right hip_sensor"
            }
          ]
          endPoint Solid {
            translation -0.045 0.18 -0.163
            rotation 0 0 -1 0.7889600000000001
            children [
              Shape {
                appearance DEF you_material PBRAppearance {
                  baseColor 0.792157 0.819608 0.933333
                  roughness 1
                  metalness 0
                }
                geometry DEF you Mesh {
                  url [
                    "D:/FxxkingCodes/Webots/FlyCar/protos/flycar/flycar/meshes/you.STL"
                  ]
                }
              }
              HingeJoint {
                jointParameters HingeJointParameters {
                  axis 0 0 1
                  anchor 0.33 0 -0.025
                }
                device [
                  RotationalMotor {
                    name "right ankle"
                    maxTorque 10000
                  }
                  PositionSensor {
                    name "right ankle_sensor"
                  }
                ]
                endPoint Solid {
                  translation 0.33 0 -0.025
                  rotation 0 0 1 1.205
                  children [
                    Shape {
                      appearance DEF youxia_material PBRAppearance {
                        baseColor 0.792157 0.819608 0.933333
                        roughness 1
                        metalness 0
                      }
                      geometry DEF youxia Mesh {
                        url [
                          "D:/FxxkingCodes/Webots/FlyCar/protos/flycar/flycar/meshes/youxia.STL"
                        ]
                      }
                    }
                    HingeJoint {
                      jointParameters HingeJointParameters {
                        axis 0 0 1
                        anchor -0.376 0 -0.035
                      }
                      device [
                        RotationalMotor {
                          name "right wheel"
                          maxTorque 10000
                        }
                        PositionSensor {
                          name "right wheel_sensor"
                        }
                      ]
                      endPoint Solid {
                        translation -0.376 0 -0.035
                        rotation 0 0 -1 0.5493
                        children [
                          Shape {
                            appearance DEF lun2_material PBRAppearance {
                              baseColor 0.792157 0.819608 0.933333
                              roughness 1
                              metalness 0
                            }
                            geometry DEF lun2 Mesh {
                              url [
                                "D:/FxxkingCodes/Webots/FlyCar/protos/flycar/flycar/meshes/lun2.STL"
                              ]
                            }
                          }
                        ]
                        name "lun2"
                        boundingObject USE lun2
                        physics Physics {
                          density -1
                          mass 0.297523
                          centerOfMass [
                            0 0 0.015
                          ]
                          inertiaMatrix [
                            0.0004360678 0.0004360678 0.000830824
                            -2.473336e-19 1.42927e-19 -3.224396e-19
                          ]
                        }
                      }
                    }
                  ]
                  name "youxia"
                  boundingObject USE youxia
                  physics Physics {
                    density -1
                    mass 0.327867
                    centerOfMass [
                      -0.194915 0 0.01
                    ]
                    inertiaMatrix [
                      0.0001051654 0.004955725 0.005039033
                      5.69545e-18 6.349727e-18 -2.82977e-20
                    ]
                  }
                }
              }
            ]
            name "you"
            boundingObject USE you
            physics Physics {
              density -1
              mass 0.254971
              centerOfMass [
                0.069414 -0.137599 -0.015
              ]
              inertiaMatrix [
                0.0003230979 0.002289071 0.002572906
                -0.000619982 2.897411e-18 9.34453e-19
              ]
            }
          }
        }
        HingeJoint {
          jointParameters HingeJointParameters {
            axis 0 0 1
            anchor -0.045 0.18 0.013
          }
          device [
            RotationalMotor {
              name "left shoulder"
              maxTorque 10000
            }
            PositionSensor {
              name "left shoulder_sensor"
            }
          ]
          endPoint Solid {
            translation -0.045 0.18 0.013
            rotation 0 0 -1 0.7889600000000001
            children [
              Shape {
                appearance DEF zuo11_material PBRAppearance {
                  baseColor 0.792157 0.819608 0.933333
                  roughness 1
                  metalness 0
                }
                geometry DEF zuo11 Mesh {
                  url [
                    "D:/FxxkingCodes/Webots/FlyCar/protos/flycar/flycar/meshes/zuo11.STL"
                  ]
                }
              }
              Solid {
                translation 0.33 0 0.005
                rotation 0 0 1 1.205
                children [
                  Shape {
                    appearance DEF zuoxia11_material PBRAppearance {
                      baseColor 0.792157 0.819608 0.933333
                      roughness 1
                      metalness 0
                    }
                    geometry DEF zuoxia11 Mesh {
                      url [
                        "D:/FxxkingCodes/Webots/FlyCar/protos/flycar/flycar/meshes/zuoxia11.STL"
                      ]
                    }
                  }
                  Solid {
                    translation -0.376 0 0.025
                    rotation 0 0 -1 0.5493
                    children [
                      Shape {
                        appearance DEF zuolun1_material PBRAppearance {
                          baseColor 0.792157 0.819608 0.933333
                          roughness 1
                          metalness 0
                        }
                        geometry DEF zuolun1 Mesh {
                          url [
                            "D:/FxxkingCodes/Webots/FlyCar/protos/flycar/flycar/meshes/zuolun1.STL"
                          ]
                        }
                      }
                    ]
                    name "zuolun1"
                    boundingObject USE zuolun1
                    physics Physics {
                      density -1
                      mass 0.297523
                      centerOfMass [
                        0 0 0.015
                      ]
                      inertiaMatrix [
                        0.0004360678 0.0004360678 0.000830824
                        -2.236167e-19 -1.579262e-19 2.714651e-19
                      ]
                    }
                  }
                ]
                name "zuoxia11"
                boundingObject USE zuoxia11
                physics Physics {
                  density -1
                  mass 0.327867
                  centerOfMass [
                    -0.194915 0 0.01
                  ]
                  inertiaMatrix [
                    0.0001051654 0.004955725 0.005039033
                    5.454892e-18 -6.638045e-18 4.652289e-20
                  ]
                }
              }
            ]
            name "zuo11"
            boundingObject USE zuo11
            physics Physics {
              density -1
              mass 0.225786
              centerOfMass [
                0.150289 0 0.015
              ]
              inertiaMatrix [
                2.885995e-05 0.001909629 0.00190276
                -8.843024e-19 -2.063367e-18 1.138668e-20
              ]
            }
          }
        }
        HingeJoint {
          jointParameters HingeJointParameters {
            axis 0 0 1
            anchor -0.045 0.18 -0.163
          }
          device [
            RotationalMotor {
              name "right shoulder"
              maxTorque 10000
            }
            PositionSensor {
              name "right shoulder_sensor"
            }
          ]
          endPoint Solid {
            translation -0.045 0.18 -0.163
            rotation 0 0 -1 0.7889600000000001
            children [
              Shape {
                appearance DEF you11_material PBRAppearance {
                  baseColor 0.792157 0.819608 0.933333
                  roughness 1
                  metalness 0
                }
                geometry DEF you11 Mesh {
                  url [
                    "D:/FxxkingCodes/Webots/FlyCar/protos/flycar/flycar/meshes/you11.STL"
                  ]
                }
              }
              Solid {
                translation 0.33 0 -0.025
                rotation 0 0 1 1.205
                children [
                  Shape {
                    appearance DEF youxia11_material PBRAppearance {
                      baseColor 0.792157 0.819608 0.933333
                      roughness 1
                      metalness 0
                    }
                    geometry DEF youxia11 Mesh {
                      url [
                        "D:/FxxkingCodes/Webots/FlyCar/protos/flycar/flycar/meshes/youxia11.STL"
                      ]
                    }
                  }
                  Solid {
                    translation -0.376 0 -0.035
                    rotation 0 0 -1 0.5493
                    children [
                      Shape {
                        appearance DEF youlun_material PBRAppearance {
                          baseColor 0.792157 0.819608 0.933333
                          roughness 1
                          metalness 0
                        }
                        geometry DEF youlun Mesh {
                          url [
                            "D:/FxxkingCodes/Webots/FlyCar/protos/flycar/flycar/meshes/youlun.STL"
                          ]
                        }
                      }
                    ]
                    name "youlun"
                    boundingObject USE youlun
                    physics Physics {
                      density -1
                      mass 0.297523
                      centerOfMass [
                        0 0 0.015
                      ]
                      inertiaMatrix [
                        0.0004360678 0.0004360678 0.000830824
                        -2.032879e-19 1.42927e-19 -3.224396e-19
                      ]
                    }
                  }
                ]
                name "youxia11"
                boundingObject USE youxia11
                physics Physics {
                  density -1
                  mass 0.327867
                  centerOfMass [
                    -0.194915 0 0.01
                  ]
                  inertiaMatrix [
                    0.0001051654 0.004955725 0.005039033
                    5.736107e-18 6.349727e-18 -2.82977e-20
                  ]
                }
              }
            ]
            name "you11"
            boundingObject USE you11
            physics Physics {
              density -1
              mass 0.225786
              centerOfMass [
                0.150289 0 -0.015
              ]
              inertiaMatrix [
                2.885995e-05 0.001909629 0.00190276
                -6.615327e-19 1.790367e-18 2.090608e-20
              ]
            }
          }
        }
      ]
      name "tou"
      boundingObject USE tou
      physics Physics {
        density -1
        mass 1.522714
        centerOfMass [
          -0.134824 0.115041 -0.075
        ]
        inertiaMatrix [
          0.01492575 0.01678215 0.01846927
          -0.0009215832 3.900003e-18 1.171373e-18
        ]
      }
    }
    Solid {
      translation -0.16883 -0.44476 0.097336
      rotation 0 0 -1 2.3562
      children [
        Shape {
          appearance DEF dianshua1_material PBRAppearance {
            roughness 1
            metalness 0
          }
          geometry DEF dianshua1 Mesh {
            url [
              "D:/FxxkingCodes/Webots/FlyCar/protos/flycar/flycar/meshes/dianshua1.STL"
            ]
          }
        }
      ]
      name "dianshua1"
      boundingObject USE dianshua1
      physics Physics {
        density -1
        mass 0.06148
        centerOfMass [
          -0.000365 -0.029994 0
        ]
        inertiaMatrix [
          9.441465e-06 4.137202e-05 3.604926e-05
          -1.352077e-07 1.058608e-20 -1.744231e-21
        ]
      }
    }
    Solid {
      translation 0.1324 -0.11524 0.097336
      rotation 0 0 1 0.7854
      children [
        Shape {
          appearance DEF dianshua2_material PBRAppearance {
            roughness 1
            metalness 0
          }
          geometry DEF dianshua2 Mesh {
            url [
              "D:/FxxkingCodes/Webots/FlyCar/protos/flycar/flycar/meshes/dianshua2.STL"
            ]
          }
        }
      ]
      name "dianshua2"
      boundingObject USE dianshua2
      physics Physics {
        density -1
        mass 0.06148
        centerOfMass [
          -0.000365 0.009994 0
        ]
        inertiaMatrix [
          9.441465e-06 4.137202e-05 3.604926e-05
          1.352077e-07 -1.563861e-20 -5.565342e-22
        ]
      }
    }
    Solid {
      translation 0.14654 -0.43061 0.097336
      rotation 0 0 -1 0.7854
      children [
        Shape {
          appearance DEF dianshua3_material PBRAppearance {
            roughness 1
            metalness 0
          }
          geometry DEF dianshua3 Mesh {
            url [
              "D:/FxxkingCodes/Webots/FlyCar/protos/flycar/flycar/meshes/dianshua3.STL"
            ]
          }
        }
      ]
      name "dianshua3"
      boundingObject USE dianshua3
      physics Physics {
        density -1
        mass 0.06148
        centerOfMass [
          -0.000365 0.009994 0
        ]
        inertiaMatrix [
          9.441465e-06 4.137202e-05 3.604926e-05
          1.352077e-07 -1.436343e-20 2.031573e-22
        ]
      }
    }
    Solid {
      translation -0.16883 -0.11524 0.097336
      rotation -0.38268083737388126 -0.9238806073826993 -2.9999987251043134e-06 3.141595
      children [
        Shape {
          appearance DEF dianshua4_material PBRAppearance {
            roughness 1
            metalness 0
          }
          geometry DEF dianshua4 Mesh {
            url [
              "D:/FxxkingCodes/Webots/FlyCar/protos/flycar/flycar/meshes/dianshua4.STL"
            ]
          }
        }
      ]
      name "dianshua4"
      boundingObject USE dianshua4
      physics Physics {
        density -1
        mass 0.06148
        centerOfMass [
          -0.000365 0.009994 0
        ]
        inertiaMatrix [
          9.441465e-06 4.137202e-05 3.604926e-05
          1.352077e-07 -9.583893e-21 -2.337466e-21
        ]
      }
    }
    Solid {
      translation -0.34032 -0.5222 0.092336
      rotation 0.9550552848467138 -0.20960606251533184 -0.20960606251533184 1.61677
      children [
        Shape {
          appearance DEF shan11_material PBRAppearance {
            baseColor 0.792157 0.819608 0.933333
            roughness 1
            metalness 0
          }
          geometry DEF shan11 Mesh {
            url [
              "D:/FxxkingCodes/Webots/FlyCar/protos/flycar/flycar/meshes/shan11.STL"
            ]
          }
        }
      ]
      name "shan11"
      boundingObject USE shan11
      physics Physics {
        density -1
        mass 0.091059
        centerOfMass [
          0.061323 -0.026197 -0.002994
        ]
        inertiaMatrix [
          0.0002661549 0.0004721584 0.0002461259
          -2.542065e-11 4.291061e-07 1.885081e-11
        ]
      }
    }
    Solid {
      translation 0.22399 -0.60211 0.092336
      rotation 0.741385924676306 0.4745249517889792 0.4745239517890808 1.865666
      children [
        Shape {
          appearance DEF shan21_material PBRAppearance {
            baseColor 0.792157 0.819608 0.933333
            roughness 1
            metalness 0
          }
          geometry DEF shan21 Mesh {
            url [
              "D:/FxxkingCodes/Webots/FlyCar/protos/flycar/flycar/meshes/shan21.STL"
            ]
          }
        }
      ]
      name "shan21"
      boundingObject USE shan21
      physics Physics {
        density -1
        mass 0.091059
        centerOfMass [
          0.061323 -0.026197 -0.002994
        ]
        inertiaMatrix [
          0.0002661549 0.0004721584 0.0002461259
          -2.542265e-11 4.29106e-07 1.88402e-11
        ]
      }
    }
    Solid {
      translation 0.30389 -0.037796 0.092336
      rotation 0.15335402975582202 0.6987441355797834 0.6987411355792013 2.837256
      children [
        Shape {
          appearance DEF shan31_material PBRAppearance {
            baseColor 0.792157 0.819608 0.933333
            roughness 1
            metalness 0
          }
          geometry DEF shan31 Mesh {
            url [
              "D:/FxxkingCodes/Webots/FlyCar/protos/flycar/flycar/meshes/shan31.STL"
            ]
          }
        }
      ]
      name "shan31"
      boundingObject USE shan31
      physics Physics {
        density -1
        mass 0.091059
        centerOfMass [
          0.061323 -0.026197 -0.002994
        ]
        inertiaMatrix [
          0.0002661549 0.0004721584 0.0002461259
          -2.537316e-11 4.291061e-07 1.885827e-11
        ]
      }
    }
    Solid {
      translation -0.26042 0.042106 0.092336
      rotation 0.4123199554673856 -0.6442029304228661 -0.6442009304230822 2.359432
      children [
        Shape {
          appearance DEF shan41_material PBRAppearance {
            baseColor 0.792157 0.819608 0.933333
            roughness 1
            metalness 0
          }
          geometry DEF shan41 Mesh {
            url [
              "D:/FxxkingCodes/Webots/FlyCar/protos/flycar/flycar/meshes/shan41.STL"
            ]
          }
        }
      ]
      name "shan41"
      boundingObject USE shan41
      physics Physics {
        density -1
        mass 0.091059
        centerOfMass [
          0.061323 -0.026197 -0.002994
        ]
        inertiaMatrix [
          0.0002661551 0.0004721585 0.0002461259
          -2.537167e-11 4.291066e-07 1.887316e-11
        ]
      }
    }
    Solid {
      translation -0.16883 -0.44476 0.097336
      rotation 0 0 -1 2.3562
      children [
        Shape {
          appearance DEF dianshau11_material PBRAppearance {
            roughness 1
            metalness 0
          }
          geometry DEF dianshau11 Mesh {
            url [
              "D:/FxxkingCodes/Webots/FlyCar/protos/flycar/flycar/meshes/dianshau11.STL"
            ]
          }
        }
      ]
      name "dianshau11"
      boundingObject USE dianshau11
      physics Physics {
        density -1
        mass 0.06148
        centerOfMass [
          -0.000365 0.009994 0
        ]
        inertiaMatrix [
          9.441465e-06 4.137202e-05 3.604926e-05
          1.352077e-07 -1.943178e-20 -4.540385e-21
        ]
      }
    }
    Solid {
      translation 0.14654 -0.12939 0.097336
      rotation 0.9238792538367837 0.382684105142855 -1.0000002747511131e-06 3.141599
      children [
        Shape {
          appearance DEF dianshua21_material PBRAppearance {
            roughness 1
            metalness 0
          }
          geometry DEF dianshua21 Mesh {
            url [
              "D:/FxxkingCodes/Webots/FlyCar/protos/flycar/flycar/meshes/dianshua21.STL"
            ]
          }
        }
      ]
      name "dianshua21"
      boundingObject USE dianshua21
      physics Physics {
        density -1
        mass 0.06148
        centerOfMass [
          -0.000365 0.009994 0
        ]
        inertiaMatrix [
          9.441465e-06 4.137202e-05 3.604926e-05
          1.352077e-07 -1.079765e-20 1.400789e-21
        ]
      }
    }
    Solid {
      translation 0.1324 -0.44476 0.097336
      rotation 0.9238792538367837 -0.382684105142855 1.0000002747511131e-06 3.141599
      children [
        Shape {
          appearance DEF dianshua31_material PBRAppearance {
            roughness 1
            metalness 0
          }
          geometry DEF dianshua31 Mesh {
            url [
              "D:/FxxkingCodes/Webots/FlyCar/protos/flycar/flycar/meshes/dianshua31.STL"
            ]
          }
        }
      ]
      name "dianshua31"
      boundingObject USE dianshua31
      physics Physics {
        density -1
        mass 0.06148
        centerOfMass [
          -0.000365 0.009994 0
        ]
        inertiaMatrix [
          9.441465e-06 4.137202e-05 3.604926e-05
          1.352077e-07 -1.256977e-20 7.701053e-23
        ]
      }
    }
    Solid {
      translation -0.18297 -0.12939 0.097336
      rotation 0 0 1 2.3562
      children [
        Shape {
          appearance DEF dianshua41_material PBRAppearance {
            roughness 1
            metalness 0
          }
          geometry DEF dianshua41 Mesh {
            url [
              "D:/FxxkingCodes/Webots/FlyCar/protos/flycar/flycar/meshes/dianshua41.STL"
            ]
          }
        }
      ]
      name "dianshua41"
      boundingObject USE dianshua41
      physics Physics {
        density -1
        mass 0.06148
        centerOfMass [
          -0.000365 0.009994 0
        ]
        inertiaMatrix [
          9.441465e-06 4.137202e-05 3.604926e-05
          1.352077e-07 -1.143248e-20 -8.804168e-22
        ]
      }
    }
  ]
  name "Flycar"
  boundingObject USE base_link
  physics Physics {
    density -1
    mass 0.650997
    centerOfMass [
      -0.018212 -0.28 0.096207
    ]
    inertiaMatrix [
      0.01475213 0.01475213 0.02944378
      -1.983167e-14 1.646443e-15 1.280474e-16
    ]
  }
}
